2023-01-28 17:01:32,956 INFO    StreamThr :35622 [internal.py:wandb_internal():88] W&B internal server running at pid: 35622, started at: 2023-01-28 17:01:32.954912
2023-01-28 17:01:32,958 DEBUG   HandlerThread:35622 [handler.py:handle_request():138] handle_request: status
2023-01-28 17:01:32,959 DEBUG   SenderThread:35622 [sender.py:send_request():317] send_request: status
2023-01-28 17:01:32,961 DEBUG   SenderThread:35622 [sender.py:send():303] send: header
2023-01-28 17:01:32,961 INFO    WriterThread:35622 [datastore.py:open_for_write():75] open: /Users/sagar/Desktop/Ace/Brovo5/wandb/run-20230128_170132-32nbj1am/run-32nbj1am.wandb
2023-01-28 17:01:32,961 DEBUG   SenderThread:35622 [sender.py:send():303] send: run
2023-01-28 17:01:36,659 ERROR   SenderThread:35622 [retry.py:__call__():154] Retry attempt failed:
Traceback (most recent call last):
  File "/Users/sagar/opt/miniconda3/envs/Bravo13/lib/python3.9/site-packages/urllib3/connection.py", line 174, in _new_conn
    conn = connection.create_connection(
  File "/Users/sagar/opt/miniconda3/envs/Bravo13/lib/python3.9/site-packages/urllib3/util/connection.py", line 72, in create_connection
    for res in socket.getaddrinfo(host, port, family, socket.SOCK_STREAM):
  File "/Users/sagar/opt/miniconda3/envs/Bravo13/lib/python3.9/socket.py", line 954, in getaddrinfo
    for res in _socket.getaddrinfo(host, port, family, type, proto, flags):
socket.gaierror: [Errno 8] nodename nor servname provided, or not known

During handling of the above exception, another exception occurred:

Traceback (most recent call last):
  File "/Users/sagar/opt/miniconda3/envs/Bravo13/lib/python3.9/site-packages/urllib3/connectionpool.py", line 703, in urlopen
    httplib_response = self._make_request(
  File "/Users/sagar/opt/miniconda3/envs/Bravo13/lib/python3.9/site-packages/urllib3/connectionpool.py", line 386, in _make_request
    self._validate_conn(conn)
  File "/Users/sagar/opt/miniconda3/envs/Bravo13/lib/python3.9/site-packages/urllib3/connectionpool.py", line 1042, in _validate_conn
    conn.connect()
  File "/Users/sagar/opt/miniconda3/envs/Bravo13/lib/python3.9/site-packages/urllib3/connection.py", line 358, in connect
    self.sock = conn = self._new_conn()
  File "/Users/sagar/opt/miniconda3/envs/Bravo13/lib/python3.9/site-packages/urllib3/connection.py", line 186, in _new_conn
    raise NewConnectionError(
urllib3.exceptions.NewConnectionError: <urllib3.connection.HTTPSConnection object at 0x11c75f4f0>: Failed to establish a new connection: [Errno 8] nodename nor servname provided, or not known

During handling of the above exception, another exception occurred:

Traceback (most recent call last):
  File "/Users/sagar/opt/miniconda3/envs/Bravo13/lib/python3.9/site-packages/requests/adapters.py", line 489, in send
    resp = conn.urlopen(
  File "/Users/sagar/opt/miniconda3/envs/Bravo13/lib/python3.9/site-packages/urllib3/connectionpool.py", line 787, in urlopen
    retries = retries.increment(
  File "/Users/sagar/opt/miniconda3/envs/Bravo13/lib/python3.9/site-packages/urllib3/util/retry.py", line 592, in increment
    raise MaxRetryError(_pool, url, error or ResponseError(cause))
urllib3.exceptions.MaxRetryError: HTTPSConnectionPool(host='api.wandb.ai', port=443): Max retries exceeded with url: /graphql (Caused by NewConnectionError('<urllib3.connection.HTTPSConnection object at 0x11c75f4f0>: Failed to establish a new connection: [Errno 8] nodename nor servname provided, or not known'))

During handling of the above exception, another exception occurred:

Traceback (most recent call last):
  File "/Users/sagar/opt/miniconda3/envs/Bravo13/lib/python3.9/site-packages/wandb/sdk/lib/retry.py", line 113, in __call__
    result = self._call_fn(*args, **kwargs)
  File "/Users/sagar/opt/miniconda3/envs/Bravo13/lib/python3.9/site-packages/wandb/sdk/internal/internal_api.py", line 213, in execute
    return self.client.execute(*args, **kwargs)  # type: ignore
  File "/Users/sagar/opt/miniconda3/envs/Bravo13/lib/python3.9/site-packages/wandb/vendor/gql-0.2.0/wandb_gql/client.py", line 52, in execute
    result = self._get_result(document, *args, **kwargs)
  File "/Users/sagar/opt/miniconda3/envs/Bravo13/lib/python3.9/site-packages/wandb/vendor/gql-0.2.0/wandb_gql/client.py", line 60, in _get_result
    return self.transport.execute(document, *args, **kwargs)
  File "/Users/sagar/opt/miniconda3/envs/Bravo13/lib/python3.9/site-packages/wandb/vendor/gql-0.2.0/wandb_gql/transport/requests.py", line 38, in execute
    request = requests.post(self.url, **post_args)
  File "/Users/sagar/opt/miniconda3/envs/Bravo13/lib/python3.9/site-packages/requests/api.py", line 115, in post
    return request("post", url, data=data, json=json, **kwargs)
  File "/Users/sagar/opt/miniconda3/envs/Bravo13/lib/python3.9/site-packages/requests/api.py", line 59, in request
    return session.request(method=method, url=url, **kwargs)
  File "/Users/sagar/opt/miniconda3/envs/Bravo13/lib/python3.9/site-packages/requests/sessions.py", line 587, in request
    resp = self.send(prep, **send_kwargs)
  File "/Users/sagar/opt/miniconda3/envs/Bravo13/lib/python3.9/site-packages/requests/sessions.py", line 701, in send
    r = adapter.send(request, **kwargs)
  File "/Users/sagar/opt/miniconda3/envs/Bravo13/lib/python3.9/site-packages/requests/adapters.py", line 565, in send
    raise ConnectionError(e, request=request)
requests.exceptions.ConnectionError: HTTPSConnectionPool(host='api.wandb.ai', port=443): Max retries exceeded with url: /graphql (Caused by NewConnectionError('<urllib3.connection.HTTPSConnection object at 0x11c75f4f0>: Failed to establish a new connection: [Errno 8] nodename nor servname provided, or not known'))
2023-01-28 17:01:37,969 DEBUG   HandlerThread:35622 [handler.py:handle_request():138] handle_request: keepalive
2023-01-28 17:01:42,997 DEBUG   HandlerThread:35622 [handler.py:handle_request():138] handle_request: keepalive
2023-01-28 17:01:48,020 DEBUG   HandlerThread:35622 [handler.py:handle_request():138] handle_request: keepalive
2023-01-28 17:01:53,040 DEBUG   HandlerThread:35622 [handler.py:handle_request():138] handle_request: keepalive
2023-01-28 17:01:58,059 DEBUG   HandlerThread:35622 [handler.py:handle_request():138] handle_request: keepalive
2023-01-28 17:02:03,072 DEBUG   HandlerThread:35622 [handler.py:handle_request():138] handle_request: keepalive
2023-01-28 17:02:08,098 DEBUG   HandlerThread:35622 [handler.py:handle_request():138] handle_request: keepalive
2023-01-28 17:02:13,117 DEBUG   HandlerThread:35622 [handler.py:handle_request():138] handle_request: keepalive
2023-01-28 17:02:18,137 DEBUG   HandlerThread:35622 [handler.py:handle_request():138] handle_request: keepalive
2023-01-28 17:02:23,160 DEBUG   HandlerThread:35622 [handler.py:handle_request():138] handle_request: keepalive
2023-01-28 17:02:28,332 DEBUG   HandlerThread:35622 [handler.py:handle_request():138] handle_request: poll_exit
2023-01-28 17:02:33,351 DEBUG   HandlerThread:35622 [handler.py:handle_request():138] handle_request: keepalive
2023-01-28 17:02:38,202 WARNING StreamThr :35622 [internal.py:is_dead():385] Internal process exiting, parent pid 35614 disappeared
2023-01-28 17:02:38,202 ERROR   StreamThr :35622 [internal.py:wandb_internal():147] Internal process shutdown.
2023-01-28 17:02:38,357 INFO    HandlerThread:35622 [handler.py:finish():814] shutting down handler
2023-01-28 17:02:38,374 INFO    WriterThread:35622 [datastore.py:close():279] close: /Users/sagar/Desktop/Ace/Brovo5/wandb/run-20230128_170132-32nbj1am/run-32nbj1am.wandb
2023-01-28 17:02:41,940 INFO    SenderThread:35622 [dir_watcher.py:__init__():216] watching files in: /Users/sagar/Desktop/Ace/Brovo5/wandb/run-20230128_170132-32nbj1am/files
2023-01-28 17:02:41,940 INFO    SenderThread:35622 [sender.py:_start_run_threads():928] run started: 32nbj1am with start time 1674954092.945226
2023-01-28 17:02:41,940 INFO    SenderThread:35622 [sender.py:finish():1331] shutting down sender
2023-01-28 17:02:41,940 INFO    SenderThread:35622 [dir_watcher.py:finish():362] shutting down directory watcher
2023-01-28 17:02:42,945 INFO    SenderThread:35622 [dir_watcher.py:finish():392] scan: /Users/sagar/Desktop/Ace/Brovo5/wandb/run-20230128_170132-32nbj1am/files
2023-01-28 17:02:42,945 INFO    SenderThread:35622 [dir_watcher.py:finish():406] scan save: /Users/sagar/Desktop/Ace/Brovo5/wandb/run-20230128_170132-32nbj1am/files/config.yaml config.yaml
2023-01-28 17:02:42,945 INFO    SenderThread:35622 [file_pusher.py:finish():168] shutting down file pusher
2023-01-28 17:02:42,945 INFO    SenderThread:35622 [file_pusher.py:join():173] waiting for file pusher
2023-01-28 17:02:43,436 INFO    Thread-15 :35622 [upload_job.py:push():143] Uploaded file /Users/sagar/Desktop/Ace/Brovo5/wandb/run-20230128_170132-32nbj1am/files/config.yaml
